<?xml version="1.0" encoding="UTF-8"?>
<!-- Generated by org.testng.reporters.JUnitReportReporter -->
<testsuite hostname="Rehaan-PC" name="com.techm.testng.DataProviderClass1" tests="8" failures="0" timestamp="19 Jun 2015 17:13:50 GMT" time="0.001" errors="4">
  <testcase name="testCaseTwo" time="0.000" classname="com.techm.testng.DataProviderClass1">
    <error type="java.lang.AssertionError" message="Failing the testCasetwo Method inside Class: class java.lang.reflect.Method">
      <![CDATA[java.lang.AssertionError: Failing the testCasetwo Method inside Class: class java.lang.reflect.Method
	at org.testng.Assert.fail(Assert.java:94)
	at com.techm.testng.DataProviderClass1.testCaseTwo(Unknown Source)
	at sun.reflect.NativeMethodAccessorImpl.invoke0(Native Method)
	at sun.reflect.NativeMethodAccessorImpl.invoke(Unknown Source)
	at sun.reflect.DelegatingMethodAccessorImpl.invoke(Unknown Source)
	at java.lang.reflect.Method.invoke(Unknown Source)
	at org.testng.internal.MethodInvocationHelper.invokeMethod(MethodInvocationHelper.java:84)
	at org.testng.internal.Invoker.invokeMethod(Invoker.java:714)
	at org.testng.internal.Invoker.invokeTestMethod(Invoker.java:901)
	at org.testng.internal.Invoker.invokeTestMethods(Invoker.java:1231)
	at org.testng.internal.TestMethodWorker.invokeTestMethods(TestMethodWorker.java:127)
	at org.testng.internal.TestMethodWorker.run(TestMethodWorker.java:111)
	at org.testng.TestRunner.privateRun(TestRunner.java:767)
	at org.testng.TestRunner.run(TestRunner.java:617)
	at org.testng.SuiteRunner.runTest(SuiteRunner.java:334)
	at org.testng.SuiteRunner.access$000(SuiteRunner.java:37)
	at org.testng.SuiteRunner$SuiteWorker.run(SuiteRunner.java:368)
	at org.testng.internal.thread.ThreadUtil$2.call(ThreadUtil.java:64)
	at java.util.concurrent.FutureTask.run(Unknown Source)
	at java.util.concurrent.ThreadPoolExecutor.runWorker(Unknown Source)
	at java.util.concurrent.ThreadPoolExecutor$Worker.run(Unknown Source)
	at java.lang.Thread.run(Unknown Source)
]]>
    </error>
  </testcase> <!-- testCaseTwo -->
  <testcase name="testCaseThree" time="0.000" classname="com.techm.testng.DataProviderClass1"/>
  <testcase name="testCaseThree" time="0.000" classname="com.techm.testng.DataProviderClass1"/>
  <testcase name="testCaseThree" time="0.000" classname="com.techm.testng.DataProviderClass1"/>
  <testcase name="testCaseTwo" time="0.000" classname="com.techm.testng.DataProviderClass1">
    <error type="java.lang.AssertionError" message="Failing the testCasetwo Method inside Class: class java.lang.reflect.Method">
      <![CDATA[java.lang.AssertionError: Failing the testCasetwo Method inside Class: class java.lang.reflect.Method
	at org.testng.Assert.fail(Assert.java:94)
	at com.techm.testng.DataProviderClass1.testCaseTwo(Unknown Source)
	at sun.reflect.NativeMethodAccessorImpl.invoke0(Native Method)
	at sun.reflect.NativeMethodAccessorImpl.invoke(Unknown Source)
	at sun.reflect.DelegatingMethodAccessorImpl.invoke(Unknown Source)
	at java.lang.reflect.Method.invoke(Unknown Source)
	at org.testng.internal.MethodInvocationHelper.invokeMethod(MethodInvocationHelper.java:84)
	at org.testng.internal.Invoker.invokeMethod(Invoker.java:714)
	at org.testng.internal.Invoker.invokeTestMethod(Invoker.java:901)
	at org.testng.internal.Invoker.invokeTestMethods(Invoker.java:1231)
	at org.testng.internal.TestMethodWorker.invokeTestMethods(TestMethodWorker.java:127)
	at org.testng.internal.TestMethodWorker.run(TestMethodWorker.java:111)
	at org.testng.TestRunner.privateRun(TestRunner.java:767)
	at org.testng.TestRunner.run(TestRunner.java:617)
	at org.testng.SuiteRunner.runTest(SuiteRunner.java:334)
	at org.testng.SuiteRunner.access$000(SuiteRunner.java:37)
	at org.testng.SuiteRunner$SuiteWorker.run(SuiteRunner.java:368)
	at org.testng.internal.thread.ThreadUtil$2.call(ThreadUtil.java:64)
	at java.util.concurrent.FutureTask.run(Unknown Source)
	at java.util.concurrent.ThreadPoolExecutor.runWorker(Unknown Source)
	at java.util.concurrent.ThreadPoolExecutor$Worker.run(Unknown Source)
	at java.lang.Thread.run(Unknown Source)
]]>
    </error>
  </testcase> <!-- testCaseTwo -->
  <testcase name="testCaseTwo" time="0.001" classname="com.techm.testng.DataProviderClass1">
    <error type="java.lang.AssertionError" message="Failing the testCasetwo Method inside Class: class java.lang.reflect.Method">
      <![CDATA[java.lang.AssertionError: Failing the testCasetwo Method inside Class: class java.lang.reflect.Method
	at org.testng.Assert.fail(Assert.java:94)
	at com.techm.testng.DataProviderClass1.testCaseTwo(Unknown Source)
	at sun.reflect.NativeMethodAccessorImpl.invoke0(Native Method)
	at sun.reflect.NativeMethodAccessorImpl.invoke(Unknown Source)
	at sun.reflect.DelegatingMethodAccessorImpl.invoke(Unknown Source)
	at java.lang.reflect.Method.invoke(Unknown Source)
	at org.testng.internal.MethodInvocationHelper.invokeMethod(MethodInvocationHelper.java:84)
	at org.testng.internal.Invoker.invokeMethod(Invoker.java:714)
	at org.testng.internal.Invoker.invokeTestMethod(Invoker.java:901)
	at org.testng.internal.Invoker.invokeTestMethods(Invoker.java:1231)
	at org.testng.internal.TestMethodWorker.invokeTestMethods(TestMethodWorker.java:127)
	at org.testng.internal.TestMethodWorker.run(TestMethodWorker.java:111)
	at org.testng.TestRunner.privateRun(TestRunner.java:767)
	at org.testng.TestRunner.run(TestRunner.java:617)
	at org.testng.SuiteRunner.runTest(SuiteRunner.java:334)
	at org.testng.SuiteRunner.access$000(SuiteRunner.java:37)
	at org.testng.SuiteRunner$SuiteWorker.run(SuiteRunner.java:368)
	at org.testng.internal.thread.ThreadUtil$2.call(ThreadUtil.java:64)
	at java.util.concurrent.FutureTask.run(Unknown Source)
	at java.util.concurrent.ThreadPoolExecutor.runWorker(Unknown Source)
	at java.util.concurrent.ThreadPoolExecutor$Worker.run(Unknown Source)
	at java.lang.Thread.run(Unknown Source)
]]>
    </error>
  </testcase> <!-- testCaseTwo -->
  <testcase name="testCaseThree" time="0.000" classname="com.techm.testng.DataProviderClass1"/>
  <testcase name="testCaseTwo" time="0.000" classname="com.techm.testng.DataProviderClass1">
    <error type="java.lang.AssertionError" message="Failing the testCasetwo Method inside Class: class java.lang.reflect.Method">
      <![CDATA[java.lang.AssertionError: Failing the testCasetwo Method inside Class: class java.lang.reflect.Method
	at org.testng.Assert.fail(Assert.java:94)
	at com.techm.testng.DataProviderClass1.testCaseTwo(Unknown Source)
	at sun.reflect.NativeMethodAccessorImpl.invoke0(Native Method)
	at sun.reflect.NativeMethodAccessorImpl.invoke(Unknown Source)
	at sun.reflect.DelegatingMethodAccessorImpl.invoke(Unknown Source)
	at java.lang.reflect.Method.invoke(Unknown Source)
	at org.testng.internal.MethodInvocationHelper.invokeMethod(MethodInvocationHelper.java:84)
	at org.testng.internal.Invoker.invokeMethod(Invoker.java:714)
	at org.testng.internal.Invoker.invokeTestMethod(Invoker.java:901)
	at org.testng.internal.Invoker.invokeTestMethods(Invoker.java:1231)
	at org.testng.internal.TestMethodWorker.invokeTestMethods(TestMethodWorker.java:127)
	at org.testng.internal.TestMethodWorker.run(TestMethodWorker.java:111)
	at org.testng.TestRunner.privateRun(TestRunner.java:767)
	at org.testng.TestRunner.run(TestRunner.java:617)
	at org.testng.SuiteRunner.runTest(SuiteRunner.java:334)
	at org.testng.SuiteRunner.access$000(SuiteRunner.java:37)
	at org.testng.SuiteRunner$SuiteWorker.run(SuiteRunner.java:368)
	at org.testng.internal.thread.ThreadUtil$2.call(ThreadUtil.java:64)
	at java.util.concurrent.FutureTask.run(Unknown Source)
	at java.util.concurrent.ThreadPoolExecutor.runWorker(Unknown Source)
	at java.util.concurrent.ThreadPoolExecutor$Worker.run(Unknown Source)
	at java.lang.Thread.run(Unknown Source)
]]>
    </error>
  </testcase> <!-- testCaseTwo -->
</testsuite> <!-- com.techm.testng.DataProviderClass1 -->
